Workbook

Sheet Read Me
A1: Premium Indian Specialty Coffee — Outreach Leads (North, West, Central, East & Northeast India)
A2: Research date: 27 Oct 2026. South India deliberately excluded (Goa is included as West coast).
A4: TIERS
A5: Premium — origin-driven specialty: single-origin / single-estate or micro-lot menus, manual brew bar (V60, Chemex, AeroPress, siphon), multi-roaster or guest-roast programmes, or imports international single origins. Core market for premium beans.
A6: Normal — better than regular: specialty-leaning, espresso-led cafes with a quality house blend, maybe one filter option; food/dessert-led concepts with a deliberate coffee programme. Market for a premium house blend + one rotating estate.
A7: Regular — commodity / chain cafes. Not targeted; listed only in 'Excluded (Regular tier)' for reference.
A9: PRIORITY
A10: A — act this week: upcoming or just-opened cafes still choosing suppliers, multi-roaster cafes, and cafes known to buy from outside roasters.
A11: B — strong fit: established Premium/Normal independents that do not roast in-house.
A12: C — nurture: roaster-owned cafes (collab/guest lot only), chains, or thin evidence.
A14: STATUS
A15: Upcoming / Coming soon — announced or 'opening soon' on social/press but not open (the pre-launch hype window).
... A34: COUNTS
A35: Cafes — total (Premium + Normal) | B35: =COUNTA('All Cafes (Premium+Normal)'!$A$2:$A$281) -> 280
A36: Cafes — Premium | B36: =COUNTIF('All Cafes (Premium+Normal)'!$D$2:$D$281,"Premium") -> 109
A37: Cafes — Normal | B37: =COUNTIF('All Cafes (Premium+Normal)'!$D$2:$D$281,"Normal") -> 171
A38: Cafes — Priority A | B38: =COUNTIF('All Cafes (Premium+Normal)'!$B$2:$B$281,"A") -> 60
A39: Hot leads (new & upcoming) | B39: =COUNTA('Hot Leads (New & Upcoming)'!$A$2:$A$91) -> 90
A40: Upcoming / coming soon | B40: =COUNTIF('All Cafes (Premium+Normal)'!$C$2:$C$281,"Upcoming / Coming soon") -> 4
A41: Opened in 2026 | B41: =COUNTIF('All Cafes (Premium+Normal)'!$C$2:$C$281,"New (opened 2026)") -> 82
A42: Multi-roaster cafes | B42: =COUNTIF('All Cafes (Premium+Normal)'!$F$2:$F$281,"Multi-roaster cafe") -> 6
A43: Cafes that roast in-house | B43: =COUNTIF('All Cafes (Premium+Normal)'!$K$2:$K$281,"Yes*") -> 12
A44: Supplier / roaster identified (not own roastery) | B44: =COUNTA('Supply Map'!$A$2:$A$51)-COUNTIF('Supply Map'!$A$2:$A$51,"Own roastery*") -> 37
A45: With an Instagram handle | B45: =COUNTIF('All Cafes (Premium+Normal)'!$U$2:$U$281,"@*") -> 110
A46: Roasters | B46: =COUNTA(Roasters!$A$2:$A$95) -> 94
A47: Channel partners | B47: =COUNTA('Channel Partners'!$A$2:$A$31) -> 30
A48: Cafes with a web check | B48: =COUNTIF('All Cafes (Premium+Normal)'!$AG$2:$AG$281,"?*") -> 262
A49: Cafe–roaster pairs from the web check | B49: =COUNTA('Web Check — Supplier Leads'!$A$2:$A$19) -> 18

Sheet Hot Leads (New & Upcoming)
A1: ID | B1: Priority | C1: Status | D1: Tier | E1: Name | F1: Type | G1: Region | H1: State | I1: City | J1: Area / address | K1: Roasts in-house? | L1: Current coffee roster | M1: Supplier / roaster | N1: Price signals | O1: Gap in their roster | P1: What we can offer | Q1: Approach strategy | R1: Evidence (why this tier) | S1: Pitch angle | T1: Best first contact | U1: Instagram | V1: Instagram URL | W1: Website | X1: Email | Y1: Phone | Z1: LinkedIn | AA1: Listing (Zomato / EazyDiner / Reddit) | AB1: Key people (public) | AC1: Source | AD1: Verify / notes | AE1: Web check: roster evidence (auto — verify) | AF1: Contacts on its own pages | AG1: Pages read (web check)
A2: C071 | B2: A | C2: Upcoming / Coming soon | D2: Premium | E2: Unnamed specialty cafe — Viman Nagar (in planning) | F2: Independent specialty cafe | G2: West | H2: Maharashtra | I2: Pune | J2: Viman Nagar | K2: Unknown | L2: Plans Coorg-sourced beans | M2: Not published — ask on first contact (look at the retail shelf / bag on the bar) | P2: Rotating single-estate / micro-lot for the filter bar + a single-origin espresso option. | Q2: Pre-launch: send a 3-estate tasting kit and offer a menu-development session before the menu locks; 90-day launch exclusivity in their micro-market; fixed price for the first 6 months. | R2: Founder posted on r/PuneCoffee (mid-2026) about opening a specialty cafe with Coorg beans and board-game nights. | S2: Pre-launch — reach founder via r/PuneCoffee before supplier is locked. | T2: Walk-in / Google Maps listing | AA2: https://www.reddit.com/r/PuneCoffee/new/ | AC2: r/PuneCoffee (via mirror redlib.groet-infra.nl/r/PuneCoffee/new) | AD2: Name unknown; Reddit post | AG2: 0 of 1 read:
A3: C174 | B3: A | C3: Upcoming / Coming soon | D3: Normal | E3: Coffee Bond (Cafe Bond) — CP & Karkardooma | F3: Cafe chain / multi-outlet | G3: North | H3: Delhi | I3: New Delhi | J3: Uday Park (South Ex II) + Saket; CP/Karkardooma outlets not confirmed | K3: Unknown | L3: Not published | M3: Not published — ask on first contact (look at the retail shelf / bag on the bar) | P3: Premium house espresso blend of Indian estates + one rotating single estate + cold-brew lot. | Q3: Pre-launch: send a 3-estate tasting kit and offer a menu-development session before the menu locks; 90-day launch exclusivity in their micro-market; fixed price for the first 6 months. | R3: Instagram bio announces 'opening soon' at Connaught Place and Karkardooma; Time Out called it an Australian import. Second handle for GK outlet: @cafebondgk. Second brand handle @thecoffeebond lists Uday Park (Delhi), Noida Sector 51 and Surat. | S3: Two launches pending — pitch before menus are fixed. | T3: Instagram DM | U3: @coffeebond | V3: https://www.instagram.com/coffeebond/ | AC3: https://www.instagram.com/coffeebond/ | AD3: Wave 4: no CP or Karkardooma listing found; Time Out calls it an Australian import. | AE3: Imported origins: Vietnam; Brew: Flat white | AG3: 3 of 4 read: https://www.explurger.com/pd/jjbnu1aqc73y2ajf6 https://www.explurger.com/pd/n1dlk70912p3g7pks https://wanderlog.com/place/details/1079729/coffee-bond
A4: C042 | B4: B | C4: Upcoming / Coming soon | D4: Premium | E4: Boojee Cafe — One BKC | F4: Roaster-cafe (roasts in-house) | G4: West | H4: Maharashtra | I4: Mumbai | J4: One BKC, Bandra Kurla Complex | K4: Yes | L4: Not published | M4: Own roastery | P4: Green coffee or a limited guest micro-lot collaboration (they roast in-house). | Q4: Don't pitch roasted supply — offer green lots or a co-branded guest micro-lot. | R4: Time Out (Aug 2026) reported Boojee's 5th Mumbai outlet opening soon at One BKC; Boojee runs as neighbourhood cafe + creative roastery. | S4: Roasts own, but expanding fast — pitch a limited guest single-estate for the BKC launch menu. | T4: Walk-in / Google Maps listing | AC4: https://www.timeout.com/mumbai/news/boojee-cafe-is-opening-a-new-outlet-at-one-bkc-in-mumbai-082026 | AD4: Wave 4: BKC still 'coming soon' (Time Out, Aug 2026); would be Boojee's 5th outlet. | AE4: Roasters named in articles about it: Boojee Cafe & Roastery; Brew: Flat white, Cold brew; ₹2,000 for two; Signals: Coming soon | AG4: 3 of 3 read: https://www.timeout.com/mumbai/news/boojee-cafe-is-opening-a-new-outlet-at-one-bkc-in-mumbai-082026 https://curlytales.com/india/food/mumbaikars-boojee-cafe-is-coming-to-bkc-with-its-signature-brews-bites/ https://www.freepressjournal.in/lifestyle/from-bandra-to-sobo-boojee-cafe-brings-its-classic-brews-brunch-to-south-mumbai
A5: C073 | B5: B | C5: Upcoming / Coming soon | D5: Normal | E5: Cafe Serenity — Baner (relocating) | F5: Independent specialty cafe | G5: West | H5: Maharashtra | I5: Pune | J5: Baner | K5: Unknown | L5: Not published | M5: Not published — ask on first contact (look at the retail shelf / bag on the bar) | P5: Premium house espresso blend of Indian estates + one rotating single estate + cold-brew lot. | Q5: Pre-launch: send a 3-estate tasting kit and offer a menu-development session before the menu locks; 90-day launch exclusivity in their micro-market; fixed price for the first 6 months. | R5: Instagram: 'Serenity finds a new home in Baner — be back soon'. | S5: Relaunch = supplier reset moment. | T5: Instagram DM | U5: @cafeserenity_pune | V5: https://www.instagram.com/cafeserenity_pune/ | AC5: https://www.instagram.com/cafeserenity_pune/ | AD5: Wave 4: only a Kothrud (Mayur Colony) listing found; Baner move unconfirmed. | AG5: 1 of 1 read: https://www.explurger.com/pd/pkfm8zlni1mxtmjw0
A6: C012 | B6: A | C6: New (opened 2026) | D6: Premium | E6: BBRWN Cafe | F6: Independent specialty cafe | G6: West | H6: Maharashtra | I6: Mumbai | J6: TBC | K6: Unknown | L6: Not published | M6: Not published — ask on first contact (look at the retail shelf / bag on the bar) | P6: Rotating single-estate / micro-lot for the filter bar + a single-origin espresso option. | Q6: Just opened: offer a guest-lot month + free barista calibration; side-by-side cupping against their current beans; ask which roaster/estates they use and what they'd change. | R6: New specialty cafe from Drishti Gundecha where coffee and ceremonial matcha take centre stage (2026 Mumbai openings coverage). | S6: New, coffee-first concept — offer espresso + filter single-estate pair. | T6: Walk-in / Google Maps listing | AB6: Drishti Gundecha (founder, per press) | AC6: Mumbai 2026 new-openings roundups (search) | AD6: Location and opening date not confirmed Instagram not indexed by search yet — look up by name on Instagram Wave 4: not found in a web search beyond its source roundup — confirm it is open (Instagram / Google Maps) before outreach.
A7: C013 | B7: A | C7: New (opened 2026) | D7: Premium | E7: Coffee Capital | F7: Cafe chain / multi-outlet | G7: West | H7: Maharashtra | I7: Mumbai | J7: Chembur + Versova (34 covers) | K7: Unknown | L7: Single-origin Arabica from Karnataka, Tamil Nadu, Odisha and Nagaland + a rotating slot of INTERNATIONAL micro-lots; whiskey-barrel-aged coffee; 'Noble Nectar'. | M7: Not published — ask on first contact (look at the retail shelf / bag on the bar) | N7: ~₹1,000 for two; EazyDiner 4.8 (249) | O7: Imports fill the 'exotic' slot. | P7: Indian anaerobic / experimental lots to replace the international micro-lot slot; barrel-ageing lots. | Q7: Lead with a cupping of 2–3 Indian experimental lots against their current import; offer the rotating slot at a fixed monthly price. | R7: 34-cover specialty cafe format built around single-origin Indian Arabica (Restaurant India). Instagram 'specialty coffee, cozy vibes — Chembur' with ~46 followers / 30 posts when indexed: account is brand-new. | S7: Menu is origin-driven — natural buyer of multiple single estates. | T7: Instagram DM | U7: @coffeecapital__ | V7: https://www.instagram.com/coffeecapital__/ | AB7: Tuhin Ghosh (founder) | AC7: https://www.restaurantindia.in/news/restaurant-india-news-coffee-capital-launches-in-mumbai-with-34-cover-speciality-caf-format.n15399 | AE7: Processes / format: Micro-lot, Single origin; Brew: Cold brew; Prices: wo at Coffee Capital? The cost of two at Coffee Capital is ₹ 1000. You can save EXTRA; ₹ 1000 for two | AG7: 2 of 3 read: https://www.eazydiner.com/mumbai/coffee-capital-versova-western-suburbs-712657 https://www.restaurantindia.in/news/restaurant-india-news-coffee-capital-launches-in-mumbai-with-34-cover-speciality-caf-format.n15399
A8: C015 | B8: A | C8: New (opened 2026) | D8: Premium | E8: Esc. Coffee x Deli | F8: Independent specialty cafe | G8: West | H8: Maharashtra | I8: Mumbai | J8: Bandra | K8: Unknown | L8: Not published | M8: Not published — ask on first contact (look at the retail shelf / bag on the bar) | P8: Rotating single-estate / micro-lot for the filter bar + a single-origin espresso option. | Q8: Just opened: offer a guest-lot month + free barista calibration; side-by-side cupping against their current beans; ask which roaster/estates they use and what they'd change. | R8: Specialty coffee spot in March 2026 openings (Foodies of India). | T8: Walk-in / Google Maps listing | AC8: https://foodiesofindia.wordpress.com/2026/03/01/new-restaurants-in-mumbai-march-2026-round-up-25-new-openings/ | AE8: ₹1500 for two | AG8: 2 of 2 read: https://www.district.in/dining/mumbai/esc-coffee-x-deli-carter-road-bandra-west https://foodiesofindia.wordpress.com/2026/03/01/new-restaurants-in-mumbai-march-2026-round-up-25-new-openings/
A9: C016 | B9: A | C9: New (opened 2026) | D9: Premium | E9: Grahm Cafe | F9: Independent specialty cafe | G9: West | H9: Maharashtra | I9: Mumbai | J9: Bandra | K9: Unknown | L9: Not published | M9: Not published — ask on first contact (look at the retail shelf / bag on the bar) | P9: Rotating single-estate / micro-lot for the filter bar + a single-origin espresso option. | Q9: Just opened: offer a guest-lot month + free barista calibration; side-by-side cupping against their current beans; ask which roaster/estates they use and what they'd change. | R9: Neighbourhood cafe for specialty coffee, fresh bakes, brunch (Foodies of India, Aug 2026). | T9: Walk-in / Google Maps listing | AC9: https://foodiesofindia.wordpress.com/2026/08/04/new-restaurants-cafes-in-mumbai-august-2026/ | AD9: Wave 4: not found in a web search beyond its source roundup — confirm it is open (Instagram / Google Maps) before outreach. | AE9: Commodity brands: Nespresso | AG9: 1 of 1 read: https://foodiesofindia.wordpress.com/2026/08/04/new-restaurants-cafes-in-mumbai-august-2026/
A10: C017 | B10: A | C10: New (opened 2026) | D10: Premium | E10: JOKER | F10: Coffee + cocktail bar | G10: West | H10: Maharashtra | I10: Mumbai | J10: Turner Rd, Bandra W (opened 2 Aug 2026) | K10: Unknown | L10: Cafe by day, cocktail bar by night; Brandy Barrel Aged pour-over; signatures Joker Twist, Frost and Fortune. | M10: Not published — ask on first contact (look at the retail shelf / bag on the bar) | O10: Barrel-aged programme needs lots that suit ageing. | P10: Co-developed barrel series (rum / brandy / whisky) on Indian naturals + cocktail-grade espresso. | Q10: Pitch Aspect Hospitality's F&B team — group can roll it out to other venues. | R10: Aspect Hospitality's all-day coffee & cocktail bar, opened 2 Aug 2026. | T10: Website contact form | W10: https://aspecthospitality.in | AB10: Aspect Hospitality | AC10: https://www.restaurantindia.in/news/aspect-hospitality-expands-fb-portfolio-with-joker-in-bandra.n16905 | AE10: Brew: Pour over | AG10: 3 of 4 read: https://aspecthospitality.in https://www.aspecthospitality.in/our-story https://www.restaurantindia.in/news/aspect-hospitality-expands-fb-portfolio-with-joker-in-bandra.n16905
A11: C019 | B11: A | C11: New (opened 2026) | D11: Premium | E11: Kink Speciality Coffee | F11: Cafe chain / multi-outlet | G11: West | H11: Maharashtra | I11: Mumbai | J11: Bandra (+ other outlets) | K11: Unknown | L11: Not published | M11: Not published — ask on first contact (look at the retail shelf / bag on the bar) | P11: Rotating single-estate / micro-lot for the filter bar + a single-origin espresso option. | Q11: Just opened: offer a guest-lot month + free barista calibration; side-by-side cupping against their current beans; ask which roaster/estates they use and what they'd change. | R11: Instagram: speciality coffee, Bandra among outlets. Foodies of India Jan 2026: bold, modern coffee spot, strong brews. | S11: Specialty indie. | T11: Instagram DM | U11: @kink.coffee | V11: https://www.instagram.com/kink.coffee/ | AC11: https://foodiesofindia.wordpress.com/2026/01/15/january-2026-30-new-restaurants-cafes-in-mumbai-you-need-to-check-out/ | AD11: Wave 4: not found in a web search beyond its source roundup — confirm it is open (Instagram / Google Maps) before outreach. | AG11: 0 of 1 read:
A12: C020 | B12: A | C12: New (opened 2026) | D12: Premium | E12: KĀPIBAR | F12: Independent specialty cafe | G12: West | H12: Maharashtra | I12: Mumbai | J12: Bandra | K12: Unknown | L12: Regional Indian coffee traditions (details not published). | M12: Not published — ask on first contact (look at the retail shelf / bag on the bar) | P12: Regional single estates (Coorg, Chikmagalur, Nilgiris, Araku, Northeast) — a 'map of India' flight. | Q12: Perfect story fit — lead with origin storytelling. | R12: South Indian-inspired cafe celebrating regional coffee traditions (Foodies of India, Aug 2026). | T12: Walk-in / Google Maps listing | AC12: https://foodiesofindia.wordpress.com/2026/08/04/new-restaurants-cafes-in-mumbai-august-2026/ | AD12: Wave 4: not found in a web search beyond its source roundup — confirm it is open (Instagram / Google Maps) before outreach. | AE12: Commodity brands: Nespresso | AG12: 1 of 1 read: https://foodiesofindia.wordpress.com/2026/08/04/new-restaurants-cafes-in-mumbai-august-2026/
A13: C021 | B13: A | C13: New (opened 2026) | D13: Premium | E13: MUVN Coffee | F13: Independent specialty cafe | G13: West | H13: Maharashtra | I13: Mumbai | J13: Andheri | K13: Unknown | L13: Not published | M13: Not published — ask on first contact (look at the retail shelf / bag on the bar) | P13: Rotating single-estate / micro-lot for the filter bar + a single-origin espresso option. | Q13: Just opened: offer a guest-lot month + free barista calibration; side-by-side cupping against their current beans; ask which roaster/estates they use and what they'd change. | R13: Listed under 'New Cafes in Andheri' (Foodies of India, Apr 2026). | T13: Walk-in / Google Maps listing | AC13: https://foodiesofindia.wordpress.com/2026/04/02/20-new-restaurants-in-mumbai-to-check-out-april-2026/ | AD13: Wave 4: not found in a web search beyond its source roundup — confirm it is open (Instagram / Google Maps) before outreach. | AG13: 1 of 1 read: https://foodiesofindia.wordpress.com/2026/04/02/20-new-restaurants-in-mumbai-to-check-out-april-2026/
A14: C022 | B14: A | C14: New (opened 2026) | D14: Premium | E14: Stand By Coffee — Juhu | F14: Cafe chain / multi-outlet | G14: West | H14: Maharashtra | I14: Mumbai | J14: Juhu (3rd outlet after Worli and Bandra) | K14: No (roasting partners) | L14: Pour-overs, espresso, matcha; first outlet with ube drinks. Seven Chikmagalur coffees from outside roasting partners. | M14: Works with outside roasting partners (unnamed) | N14: ₹600–1,700 for two | O14: Single-region roster (Chikmagalur only). | P14: Non-Chikmagalur estates (Northeast, Araku, Nilgiris, Odisha, Coorg) to diversify the 7-coffee wall. | Q14: Group pitch for all three outlets: offer a non-Karnataka estate as a guest pour-over across Worli, Bandra and Juhu. | R14: Mumbai-born cafe brand opened 3rd outlet in Juhu; menu has espresso, pour-over, matcha and ube drinks. Instagram bio: 7:30am–1am, phone numbers listed in bio, on Zomato/Swiggy. | S14: Growing indie brand with pour-over on menu — pitch rotating single-estate filter offering. | T14: Instagram DM | U14: @standbycoffee__ | V14: https://www.instagram.com/standbycoffee__/ | AB14: Aditya Wanwari (Toast Inc) | AC14: https://indianretailer.com/news/stand-coffee-expands-mumbai-footprint-new-juhu-outlet | AE14: Indian origins/estates: Chikmagalur; Brew: Pour over, Espresso tonic | AG14: 2 of 3 read: https://indianretailer.com/news/stand-coffee-expands-mumbai-footprint-new-juhu-outlet https://www.restaurantindia.in/news/stand-by-coffee-unveils-in-mumbai.n21574
A15: C023 | B15: A | C15: New (opened 2026) | D15: Premium | E15: Thought Coffee — Bandra flagship | F15: Cafe chain / multi-outlet | G15: West | H15: Maharashtra | I15: Mumbai | J15: Bandra | K15: Yes — 'single-estate AA, roasted in-house' (Restaurant India) | L15: Single-estate AA Arabica roasted in-house; rum- and wine-barrel-aged coffees; imported Colombian Castillo special; QSR under 5 minutes. | M15: Own roastery (single-estate AA, roasted in-house) | O15: Imports Colombian Castillo for its special; a QSR brand scaling across Mumbai needs volume + consistency. | P15: Green coffee (single-estate AA + an Indian replacement for the Castillo) for their roaster. | Q15: They roast: pitch green lots and an exclusive barrel-ageing lot as they densify across Mumbai. | R15: Mumbai-born quick-service specialty brand opening its Bandra flagship (Oct 2026 roundups); menu lists single-origin AA Arabica and barrel-aged coffees. Wave 4: Restaurant India (Sep 2026) says the beans are roasted in-house. | S15: Young brand building a menu of 'special' coffees — barrel-aged / experimental-process lots fit. | T15: Walk-in / Google Maps listing | AB15: Kush Kachhara, Kshitij Patil, Jhanvi Shah (founders) | AC15: https://www.restaurantindia.in/news/thought-coffee-opens-bandra-flagship-as-mumbai-quick-service-coffee-market-expands.n17296 | AD15: Instagram not indexed by search yet — look up by name on Instagram | AE15: Imported origins: Colombia; Processes / format: Single origin, Single estate | AG15: 2 of 3 read: https://www.restaurantindia.in/news/thought-coffee-opens-bandra-flagship-as-mumbai-quick-service-coffee-market-expands.n17296 https://www.passionateinmarketing.com/one-less-thought-thought-coffee-opens-in-bandra-with-quality-coffee/
A16: C024 | B16: A | C16: New (opened 2026) | D16: Premium | E16: Tsubaki Artisanal Coffee | F16: Independent specialty cafe | G16: West | H16: Maharashtra | I16: Mumbai | J16: Kandivali | K16: Unknown | L16: Not published | M16: Not published — ask on first contact (look at the retail shelf / bag on the bar) | P16: Suburban specialty with little competition — exclusive estates. | Q16: Just opened: offer a guest-lot month + free barista calibration; side-by-side cupping against their current beans; ask which roaster/estates they use and what they'd change. | R16: New artisanal coffee spot (Foodies of India, Jun 2026). | T16: Walk-in / Google Maps listing | AC16: https://foodiesofindia.wordpress.com/2026/06/01/june-2026-new-restaurants-in-mumbai-you-need-to-visit/ | AD16: Wave 4: not found in a web search beyond its source roundup — confirm it is open (Instagram / Google Maps) before outreach. | AG16: 1 of 1 read: https://foodiesofindia.wordpress.com/2026/06/01/june-2026-new-restaurants-in-mumbai-you-need-to-visit/
A17: C068 | B17: A | C17: New (opened 2026) | D17: Premium | E17: Cafe Lento — Pune | F17: All-day / food-led cafe | G17: West | H17: Maharashtra | I17: Pune | J17: Koregaon Park | K17: Unknown | L17: Single estate: Salawara Estate (Karnataka); coffee is the signature; Pune adds cocktails (raw mango wine, Lento espresso martini). | M17: Salawara Estate (roaster not named) | O17: Single-estate dependency. | P17: Second estate for a rotating pour-over + an espresso-martini-ready blend. | Q17: Luna Hospitality (also The Second House, Goa) — one pitch covers Goa + Pune. | R17: Luna Hospitality's Goa cafe opened a 2,200 sq ft Pune outpost (Nod Jun 2026; Elle Decor Sep 2026); coffee + congee concept. | S17: Single-estate-minded team — pitch an estate exclusive for Pune. | T17: Instagram DM | U17: @cafelento.in | V17: https://www.instagram.com/cafelento.in/ | AB17: Dishant Pritamani (co-founder, Luna Hospitality) | AC17: https://yourstory.com/ys-life/the-second-house-goa-lento-cafe | AG17: 0 of 2 read:
A18: C069 | B18: A | C18: New (opened 2026) | D18: Premium | E18: Momoka | F18: Independent specialty cafe | G18: West | H18: Maharashtra | I18: Pune | J18: Prabhat Rd, Pune (opened 1 Aug 2026) | K18: Unknown | L18: Japanese kissaten: ceremonial Uji matcha, hojicha; coffee jelly latte, coconut-foam cold brew. | M18: Not published — ask on first contact (look at the retail shelf / bag on the bar) | N18: ~₹900 for two | O18: Coffee is secondary to matcha; no named roaster. | P18: A kissaten-style medium-dark blend + a cold brew lot. | Q18: Chef-founder Brainard Colaco — offer to co-design a hand-drip menu. | R18: Japanese kissaten-style flagship opened Aug 2026 with specialty beverages, desserts and yoshoku food. Instagram bio: 'India's first kissaten' — Japanese coffee & tea room; Prabhat Road marked 'now open' (Jul 2026). | S18: Kissaten culture = hand-drip / siphon — pitch light-roast single estates. | T18: Instagram DM | U18: @momoka.india | V18: https://www.instagram.com/momoka.india/ | AB18: Chef Brainard Colaco | AC18: https://www.restaurantindia.in/news/momoka-opens-japanese-kissaten-inspired-caf-on-punes-prabhat-road.n16884 | AE18: Brew: Cold brew | AG18: 3 of 3 read: https://www.restaurantindia.in/news/momoka-opens-japanese-kissaten-inspired-caf-on-punes-prabhat-road.n16884 https://indianretailer.com/franchisetv/archives/news/momoka-brings-japanese-kissaten-culture-pune-new-flagship-cafe https://www.passionateinmarketing.com/momoka-brings-the-spirit-of-a-japanese-kissaten-to-pune/
A19: C124 | B19: A | C19: New (opened 2026) | D19: Premium | E19: Indiroom (at Pincode Bungalow) | F19: Independent specialty cafe | G19: West | H19: Goa | I19: Assagao | K19: No | L19: Indian specialty coffee roasted by Caarabi. | M19: Caarabi Coffee (New Delhi) | O19: Single-roaster. | P19: Second roaster / Goa-exclusive estate. | Q19: Approach via Pincode by Kunal Kapur team. | R19: Opened Feb 2026; serves Indian specialty coffee roasted by Caarabi Coffee, New Delhi. | S19: Proven external-roaster buyer — pitch as second/rotating roaster. | T19: Walk-in / Google Maps listing | U19: (via @pincode_india) | AB19: Inside Pincode by chef Kunal Kapur (@pincode_india) | AC19: https://www.district.in/blog/speciality-coffee-cafes-goa | AE19: Roasters named in articles about it: Caarabi Coffee Roasters; Brew: Tasting flight / omakase, V60, Pour over, Cold brew | AG19: 1 of 2 read: https://www.baristamagazine.com/exploring-the-vibrant-specialty-coffee-culture-of-goa-india/
A20: C156 | B20: A | C20: New (opened 2026) | D20: Premium | E20: More Over Coffee | F20: Cafe chain / multi-outlet | G20: Central | H20: Chhattisgarh | I20: Raipur | J20: Civil Lines + Devendra Nagar (Raipur), Nehru Nagar (Bhilai), Vyapar Vihar (Bilaspur) | K20: Unknown | L20: 'No long menu' — six drinks at a specialty bar (est. 2024). | M20: Not published — ask on first contact (look at the retail shelf / bag on the bar) | P20: Rotating single-estate / micro-lot for the filter bar + a single-origin espresso option. | Q20: Just opened: offer a guest-lot month + free barista calibration; side-by-side cupping against their current beans; ask which roaster/estates they use and what they'd change. | R20: Instagram: 'Speciality Coffee & More' — relaunched in Civil Lines, Raipur. Instagram lists 4 outlets across Raipur, Bhilai and Bilaspur — Chhattisgarh's only specialty-labelled multi-outlet brand. | S20: Relaunch + pour-over menu — Raipur's lone specialty lead. | T20: Instagram DM | U20: @moreovercoffee_india | V20: https://www.instagram.com/moreovercoffee_india/ | AC20: https://www.instagram.com/moreovercoffee_india/ | AD20: Wave 4: the only web page found is a demo site (moc-demo.vercel.app) — not used as its website. | AG20: 0 of 1 read:
A21: C158 | B21: A | C21: New (opened 2026) | D21: Premium | E21: Carbon — Vaishali Nagar (3rd outpost) | F21: Cafe chain / multi-outlet | G21: North | H21: Rajasthan | I21: Jaipur | J21: Ashok Nagar, Tilak Nagar, Vaishali Nagar (Jaipur) | K21: Unknown | L21: 18–96-hour cold brews (berry, mint-lime, whiskey barrel), Black Carbon Latte, Jamun Coffee Tonic, coffee mixology. | M21: Not published — ask on first contact (look at the retail shelf / bag on the bar) | N21: ~₹900 for two; Whiskey Barrel Cold Brew ₹220 | O21: Cold-brew-heavy menu across 3 outlets. | P21: Cold-brew-optimised naturals in bulk + espresso blend; co-developed coffee tonic. | Q21: 3-outlet local brand — pitch volume pricing. | R21: Third outpost pairing specialty coffee with a design-forward space (2026 roundup). Instagram: craft coffee bar, cold-brew focus, 9am–midnight. | S21: Expanding local brand. | T21: Instagram DM | U21: @carbon.jaipur | V21: https://www.instagram.com/carbon.jaipur/ | AC21: https://www.restaurantindia.in/news/carbon-opens-third-caf-in-jaipur-with-new-vaishali-nagar-outlet.n16924 | AD21: Single source | AE21: Imported origins: Vietnam; Processes / format: Experimental lot; Brew: Cold brew, V60, Siphon; Prices: Whiskey Cold Brew, INR 220 | Vanilla Strawberry Iced Latte, INR 220; ₹ 900 for two | AG21: 5 of 5 read: https://www.eazydiner.com/jaipur/carbon-ashok-nagar-jaipur-690551/reviews https://www.restaurantindia.in/news/carbon-opens-third-caf-in-jaipur-with-new-vaishali-nagar-outlet.n16924 https://curlytales.com/india/food/whiskey-barrel-cold-brew-to-au-chocolate-carbon-brings-a-new-cafe-culture-in-jaipur/ https://indianretailer.com/news/carbon-jaipur-expands-second-outlet-jaipur-cafe-market
A22: C159 | B22: A | C22: New (opened 2026) | D22: Premium | E22: Jacob's Brew House — Jaipur | F22: Cafe chain / multi-outlet | G22: North | H22: Rajasthan | I22: Jaipur | J22: JLN Marg, Malviya Nagar | K22: Likely in-house ('controlled roasting') | L22: Pour-over and espresso with tasting cards (origin, farm, producer, process, roast); signatures The Jacobs Sensation, Cloud 101. | M22: Not published — ask on first contact (look at the retail shelf / bag on the bar) | N22: ~₹1,500 for two | O22: Sophisticated, card-driven menu that needs a steady supply of traceable lots. | P22: Competition-grade lots with full farm data (green or roasted); co-branded tasting cards. | Q22: Speak to the coffee lead directly: send farm-level lot sheets — their tasting-card format rewards traceable single estates. | R22: Opened Mar 2026; design-led all-day cafe; specialty programme led by UAE Barista Champion Sonam Dorje Sherpa. | S22: Champion-led programme = appetite for competition-grade lots. | T22: Walk-in / Google Maps listing | AB22: Sonam Dorje Sherpa (UAE Barista Champion) leads the coffee programme | AC22: https://thenodmag.com/content/jacobs-brew-house-jaipur-cafe-coffee-house-review | AD22: Instagram unconfirmed (@jacobs_brew may be a different shop) | AE22: Imported origins: Vietnam; Brew: Cold brew, Pour over; Signals: Now open | AG22: 4 of 4 read: https://thenodmag.com/content/jacobs-brew-house-jaipur-cafe-coffee-house-review https://www.restaurantindia.in/news/restaurant-india-news-jacob-s-brew-house-brings-specialty-coffee-focus-to-jaipur.n15791 https://www.restaurantindia.in/news/restaurant-india-news-jacob-s-brew-house-opens-in-jaipur-introducing-a-design-led-specialty-coffee.n15452 https://oteats.outlooktraveller.com/amp/story/reviews/the-pesto-gnocchi-at-jacobs-is-all-you-need-to-make-sundays-saucy
A23: C160 | B23: A | C23: New (opened 2026) | D23: Premium | E23: Traut Coffee House | F23: Independent specialty cafe | G23: North | H23: Rajasthan | I23: Jaipur | J23: A-2, Ajmer Rd, Vidhyut Nagar | K23: Unknown | L23: Signature Pistachio Crème Latte; espresso-led. | M23: Not published — ask on first contact (look at the retail shelf / bag on the bar) | N23: ~₹800 for two | O23: No published filter / single-origin line. | P23: Espresso blend that holds up in milk + one single-estate filter to add depth. | Q23: Weeks-old, founder-run — walk-in tasting with founders Aalia Agarwal & Ujjwal Bijarnia. | R23: Outlook Traveller (26 Sep 2026): Jaipur's newest coffee hotspot, inventive coffee + broad food menu. Weekend queues reported; open till 11pm. | S23: Opened weeks ago — supplier relationships still forming. | T23: Walk-in / Google Maps listing | AA23: https://www.eazydiner.com/jaipur/traut-coffee-house-vidhyut-nagar-jaipur-719695 | AB23: Aalia Agarwal & Ujjwal Bijarnia (founders) | AC23: https://www.outlooktraveller.com/ot-pours/traut-coffee-house-opens-doors-as-jaipurs-newest-coffee-hotspot | AD23: Instagram not indexed by search yet — look up by name on Instagram | AE23: Imported origins: Java; Prices: aut Coffee House? The cost of two at Traut Coffee House is ₹ 800. You can save EXTRA; ₹ 800 for two | AG23: 2 of 2 read: https://www.eazydiner.com/jaipur/traut-coffee-house-vidhyut-nagar-jaipur-719695 https://www.outlooktraveller.com/ot-pours/traut-coffee-house-opens-doors-as-jaipurs-newest-coffee-hotspot
A24: C177 | B24: A | C24: New (opened 2026) | D24: Premium | E24: Common Time — Khan Market | F24: Cafe chain / multi-outlet | G24: North | H24: Delhi | I24: New Delhi | J24: Khan Market (Khan Kissaten) + Lodhi Colony + Basant Lok | K24: Unknown | L24: Rotating single-origin pour-overs; iced brown-butter latte, Earl Grey flat white, Competition Latte; no syrups. | M24: Not published — ask on first contact (look at the retail shelf / bag on the bar) | P24: Hand-drip single estates + kissaten blend. | Q24: Group deal with Bhatia Hospitality: Common Time (3 outlets) + Sidewalk (5 outlets) — pitch a rotating single-origin for Common Time and a house blend for Sidewalk. | R24: Time Out review 4/5. Lab Mag (Sep 2026): hidden cafe drawing on Japanese kissaten culture — design, music, coffee. | S24: Blend + single estate. | T24: Walk-in / Google Maps listing | AB24: Jaivardhan & Sagar Bhatia (Bhatia Hospitality Group) | AC24: https://www.thelabmagofficial.com/new-restaurants-cafes-and-bars-to-try-across-india-this-september/ | AE24: Processes / format: Single origin; Brew: Pour over, Cold brew, Flat white | AG24: 3 of 4 read: https://www.timeout.com/delhi/restaurants/common-time https://www.restaurantindia.in/news/restaurant-india-news-common-time-opens-second-delhi-caf-in-basant-lok-targets-premium-neighbourhood.n15317 https://indianretailer.com/news/common-time-opens-second-delhi-cafe-basant-lok-market
A25: C178 | B25: A | C25: New (opened 2026) | D25: Premium | E25: Cortasso Coffee and Bakehouse | F25: Bakery / patisserie cafe | G25: North | H25: Delhi | I25: New Delhi | J25: Sunder Nursery, Nizamuddin | K25: Unknown | L25: Rum-barrel-aged roast coffee, winter spice latte; opened 2025. | M25: Not published — ask on first contact (look at the retail shelf / bag on the bar) | P25: Rotating single-estate / micro-lot for the filter bar + a single-origin espresso option. | Q25: Just opened: offer a guest-lot month + free barista calibration; side-by-side cupping against their current beans; ask which roaster/estates they use and what they'd change. | R25: Named in The Nod's 'new wave' of south Delhi coffee (May 2026). | T25: Walk-in / Google Maps listing | AC25: https://thenodmag.com/content/the-drop-hauz-khas-delhi-indian-specialty-coffee-roastery-review | AE25: Processes / format: Guest roaster / rotating | AG25: 2 of 4 read: https://thenodmag.com/content/the-drop-hauz-khas-delhi-indian-specialty-coffee-roastery-review https://urbanaut.app/spot/delhi-coffee-crawl-7
A26: C179 | B26: A | C26: New (opened 2026) | D26: Premium | E26: In Good Co. | F26: Independent specialty cafe | G26: North | H26: Delhi | I26: New Delhi | J26: GK-2 (first outlet) | K26: Unknown | L26: 'Progressive Indianness': Americano beside filter coffee; signatures The Indulgent, The Romantic, The Optimist, The Conversationalist; hojicha mocha. | M26: Not published — ask on first contact (look at the retail shelf / bag on the bar) | N26: ~₹800 for two; Swiggy 4.2 | O26: One-origin roster (Chikkamagaluru AA) — no rotating filter or second region. | P26: Second estate for a rotating filter / seasonal special; Indian-origin storytelling to match its 'modern Indian' positioning. | Q26: Corporate-backed (Aditya Birla dining) — pitch a supply partnership for future outlets; Instagram DM + LinkedIn to the dining arm. | R26: Cafe-meets-cultural-hub built around coffee, food and community (The Nod, Jun 2026). Instagram: 'India's good coffee in good company' — modern Indian cafe, specialty coffee & comfort food; account sits under Aditya Birla dining (~5.2k followers). Corporate-backed: likely to add outlets. | S26: Corporate-backed concept with expansion potential — pitch a supply partnership, not a single bag. | T26: Instagram DM | U26: @ingoodcoindia | V26: https://www.instagram.com/ingoodcoindia/ | AC26: https://thenodmag.com/content/where-to-eat-this-june-in-delhi-ncr | AE26: Indian origins/estates: Chikmagalur; Imported origins: Vietnam; Processes / format: Single estate; Brew: Cold brew, Tasting flight / omakase; ₹800 for two | AG26: 3 of 5 read: https://thenodmag.com/content/where-to-eat-this-june-in-delhi-ncr https://curlytales.com/delhis-in-good-co-pampered-me-with-upma-balls-tahini-coffee-in-a-baby-blue-setting/ https://www.outlooktraveller.com/ot-pours/the-sulaimani-iced-tea-at-in-good-co-is-enough-reason-to-plan-a-visit
A27: C180 | B27: A | C27: New (opened 2026) | D27: Premium | E27: The Drop | F27: Coffee + cocktail bar | G27: North | H27: Delhi | I27: New Delhi | J27: G-8, Ground Floor, Hauz Khas Market (35 seats) | K27: No (Subko collaboration) | L27: House blend developed with Subko from Tamil Nadu estates (Orchardale, Bison Valley, Moganad); agave-barrel-aged (Maya Pistola) hot and iced pour-overs; new menu monthly. | M27: Developed with Subko (Mumbai) | N27: ₹1,000–1,800 for two (Swiggy / EazyDiner / OT) | O27: All-Tamil Nadu, single-partner line-up; no Northeast, Karnataka, Odisha or Araku coffees; rotation needs new lots every month. | P27: A guest 'drop' month of non-TN estates (Northeast / Odisha / Karnataka micro-lot or co-ferment), co-branded limited release. | Q27: Pitch Passcode Hospitality (also runs Saz, Jamun, PCO) — one deal can travel across the group. Lead with a 3-lot cupping flight. | R27: Passcode Hospitality's coffee-and-cocktail bar (May 2026); rotates its craft coffee menu monthly. | S27: Monthly rotation needs new lots — pitch a guest month featuring your estates. | T27: Website contact form | W27: https://passcodehospitality.com/drop | AB27: Passcode Hospitality | AC27: https://www.outlooktraveller.com/ot-pours/drop-in-at-the-drop-and-find-your-jaws-dropped | AD27: Instagram not indexed by search yet — look up by name on Instagram | AE27: Roasters named in articles about it: Subko Coffee Roasters; Indian origins/estates: Tamil Nadu; Imported origins: Colombia; Processes / format: Guest roaster / rotating, Single origin, House blend; Varietals: Robusta; Brew: Pour over | AF27: +91 98109 61802 | AG27: 5 of 6 read: https://passcodehospitality.com/drop https://passcodehospitality.com/about-us https://passcodehospitality.com/brands/drop/menu/ https://www.outlooktraveller.com/ot-pours/drop-in-at-the-drop-and-find-your-jaws-dropped
A28: C181 | B28: A | C28: New (opened 2026) | D28: Premium | E28: Therefore | F28: Coffee + cocktail bar | G28: North | H28: Delhi | I28: New Delhi | J28: Meherchand Market, Lodhi Colony | K28: Unknown | L28: Not published | M28: Not published — ask on first contact (look at the retail shelf / bag on the bar) | P28: Rotating single-estate / micro-lot for the filter bar + a single-origin espresso option. | Q28: Just opened: offer a guest-lot month + free barista calibration; side-by-side cupping against their current beans; ask which roaster/estates they use and what they'd change. | R28: All-day cafe turning cocktail bar; specialty coffee on menu (Outlook Traveller, 21 Oct 2026). | S28: Days-old opening — fastest-moving lead in Delhi. | T28: Walk-in / Google Maps listing | AC28: https://www.outlooktraveller.com/ot-pours | AD28: Only one press mention (OT Pours, Oct 2026) — confirm name/handle Wave 4: not found in a web search beyond its source roundup — confirm it is open (Instagram / Google Maps) before outreach. | AG28: 0 of 1 read:
A29: C202 | B29: A | C29: New (opened 2026) | D29: Premium | E29: Altogether Experimental (ATE) — Omakase | F29: Independent specialty cafe | G29: North | H29: Haryana | I29: Gurugram | J29: Sector 59, Gurugram | K29: Unknown | L29: Six-seat coffee omakase ('Textures': ethereal, slippery, syrupy, transient); Peru Geisha, clarified coffee, whiskey-barrel-aged course. | M29: Caarabi Coffee (sister company; format pioneered by Caarabi) | N29: Ticketed via District | O29: Uses an imported Peru Geisha for the headline course. | P29: An Indian rare-lot course (e.g. a Geisha/SL795 micro-lot) to replace the import. | Q29: Hard to displace Caarabi as house roaster — pitch a single omakase course / limited edition rather than supply. | R29: May 2026: four-course coffee + dessert omakase, iced pour-overs to dessert-like brews; bookings on District. Instagram ~24k followers; sister accounts @ate_patisserie, @ate_mini — 4+ outlets. Wave 4: Restaurant India says the omakase format comes from Caarabi Coffee, ATE's sister company. | S29: Omakase = curated rare lots — pitch micro-lots & experimental processes. | T29: Instagram DM | U29: @ate_altogetherexperimental | V29: https://www.instagram.com/ate_altogetherexperimental/ | AB29: Chef Anukriti Anand (founder; Instagram @chefanukritianand) | AC29: https://thenodmag.com/content/new-restaurants-bars-menus-delhi-may-2026 | AE29: Imported origins: Colombia, Costa Rica; Processes / format: Experimental lot; Varietals: Geisha / Gesha; Brew: Tasting flight / omakase, Affogato, Cold brew, Cortado; Commodity brands: Starbucks; Prices: Coffee • ₹1200 for two | Coffee • ₹2500 for two | ₹2500 for two • Coffee • Continental; ₹1200 for two | AG29: 6 of 7 read: https://thenodmag.com/content/new-restaurants-bars-menus-delhi-may-2026 https://www.restaurantindia.in/news/restaurant-india-news-ate-omakase-introduces-omakase-style-coffee-format-in-gurugram.n16015 https://www.indianretailer.com/franchisetv/archives/news/ate-omakase-introduces-curated-coffee-format-gurugram https://www.esquireindia.co.in/amp/story/food-and-drinks/where-to-drink/ate-omakase-coffee-in-gurgaon
A30: C203 | B30: A | C30: New (opened 2026) | D30: Premium | E30: Oro | F30: Independent specialty cafe | G30: North | H30: Haryana | I30: Gurugram | K30: Unknown | L30: Beans from North East India, Goa and Tamil Nadu; pour-over or classic; tiramisu latte, chocolate-berry cold brew. | M30: Not published — ask on first contact (look at the retail shelf / bag on the bar) | O30: No Karnataka / Coorg / Araku / Odisha coffees on the published list. | P30: An exclusive estate for the flagship plus supply for the planned NCR outlets. | Q30: Founder-led (Tisha Aggarwal) — founder outreach with a tasting kit; position as expansion partner. | R30: Flagship opened Aug/Sep 2026 by Tisha Aggarwal; plans NCR expansion. Curly Tales Oct 2026: 'new specialty coffee and all-day cafe in Gurgaon… design-led space'. | S30: Already multi-origin buyer — add your estate; future NCR outlets. | T30: Walk-in / Google Maps listing | AB30: Tisha Aggarwal (founder) | AC30: https://www.restaurantindia.in/news/oro-opens-flagship-specialty-coffee-caf-in-gurugram.n17284 | AD30: Instagram not indexed by search yet — look up by name on Instagram | AE30: Indian origins/estates: Tamil Nadu; Brew: Pour over, Cold brew | AG30: 2 of 2 read: https://www.restaurantindia.in/news/oro-opens-flagship-specialty-coffee-caf-in-gurugram.n17284 https://indianretailer.com/franchisetv/archives/news/specialty-coffee-brand-oro-opens-flagship-cafe-gurugram
A31: C213 | B31: A | C31: New (opened 2026) | D31: Premium | E31: Lumie — Fine Bakes & Speciality Coffee | F31: Bakery / patisserie cafe | G31: North | H31: Uttar Pradesh | I31: Lucknow | K31: Unknown | L31: Not published | M31: Not published — ask on first contact (look at the retail shelf / bag on the bar) | P31: Rotating single-estate / micro-lot for the filter bar + a single-origin espresso option. | Q31: Just opened: offer a guest-lot month + free barista calibration; side-by-side cupping against their current beans; ask which roaster/estates they use and what they'd change. | R31: Newer spot: croissants, desserts, specialty coffee (Knocksense). | T31: Walk-in / Google Maps listing | AC31: https://www.knocksense.com/lucknow/5-new-coffee-spots-in-lucknow-worth-adding-to-your-caf%C3%A9-hopping-list | AD31: Wave 4: not found in a web search beyond its source roundup — confirm it is open (Instagram / Google Maps) before outreach. | AG31: 0 of 1 read:
A32: C214 | B32: A | C32: New (opened 2026) | D32: Premium | E32: One PourCent | F32: Independent specialty cafe | G32: North | H32: Uttar Pradesh | I32: Lucknow | J32: Satya Tower, Vibhuti Khand, Gomti Nagar | K32: Unknown | L32: Known for cold coffee; reviews mixed on espresso. | M32: Not published — ask on first contact (look at the retail shelf / bag on the bar) | P32: Rotating single-estate / micro-lot for the filter bar + a single-origin espresso option. | Q32: Just opened: offer a guest-lot month + free barista calibration; side-by-side cupping against their current beans; ask which roaster/estates they use and what they'd change. | R32: Just opened (Jan 2026): coffee 'tested, tasted and trusted' (Knocksense). | T32: Walk-in / Google Maps listing | AC32: https://www.knocksense.com/lucknow/5-new-coffee-spots-in-lucknow-worth-adding-to-your-caf%C3%A9-hopping-list | AE32: ₹ 1200 for two; Signals: Coming soon | AG32: 3 of 4 read: https://www.eazydiner.com/lucknow/one-pourcent-gomti-nagar-lucknow-712033 https://www.knocksense.com/lucknow/5-new-coffee-spots-in-lucknow-worth-adding-to-your-caf%C3%A9-hopping-list https://www.knocksense.com/lucknow/5-new-coffee-spots-in-lucknow-worth-adding-to-your-café-hopping-list
A33: C250 | B33: A | C33: New (opened 2026) | D33: Premium | E33: Flameback Cafe & Kitchen | F33: All-day / food-led cafe | G33: East | H33: West Bengal | I33: Kolkata | J33: Purna Das Rd (25 seats) + new Tilak Rd outpost near Lake Mall (1,000 sq ft) | K33: Unknown | L33: Ethiopian Guji-grade and Colombian brews; specialty teas (second-flush Darjeeling, Risheehat Muscatel). | M33: Not published — ask on first contact (look at the retail shelf / bag on the bar) | O33: Coffee roster is 100% imported. | P33: Indian single estates — Northeast / Darjeeling-region coffee fits a Kolkata tea-and-coffee story. | Q33: Second outlet just opened — pitch an Indian estate for the Tilak Road menu. | R33: Original 500 sq ft cafe opened 2025; t2 'New cafe alert' on 1,000 sq ft Tilak Road extension. | S33: Expanding + imports beans — pitch Indian single estates. | T33: Walk-in / Google Maps listing | AB33: Shriti Pattanayak (owner) | AC33: https://t2online.in/goodlife/food-beverage/flameback-cafe---kitchen-is-where-global-flavours-pair-up-with-world-coffee--t2-checked-it-out/2001719 | AD33: Instagram not indexed by search yet — look up by name on Instagram | AE33: Imported origins: Ethiopia, Guji, Colombia; ₹800 for two | AG33: 2 of 2 read: https://t2online.in/goodlife/food-beverage/flameback-cafe---kitchen-is-where-global-flavours-pair-up-with-world-coffee--t2-checked-it-out/2001719 https://t2online.in/goodlife/food-beverage/new-cafe-alert--why-flameback-s-cozy-tilak-road-outpost-is-the-ultimate-hangout-spot-for-your-squad/2006388
A34: C007 | B34: A | C34: New (opened 2026) | D34: Normal | E34: Brevé (Running Late by Brevé) | F34: Independent specialty cafe | G34: West | H34: Maharashtra | I34: Mumbai | J34: Brevé 2.0, Shop G-2 Mount Apartment, St John Baptist Rd, Bandra W | K34: Unknown | L34: Espresso-led specialty menu alongside build-your-own breakfast boards; 36 seats; runs Mumbai's first cafe-led run club ('Running Late'). | M34: Not published — ask on first contact (look at the retail shelf / bag on the bar) | N34: ~₹1,000 for two | P34: Co-branded run-club blend, post-run cold brew, retail bags for the community. | Q34: Pitch a 'post-run' cold brew + a rotating single estate; offer to sponsor a run-club morning with a tasting of 3 Indian estates. | R34: 36-seat flagship built around 'Mumbai's first cafe-led run club'; Brevé Bakery (Bandra W) and 'Basque by breve' also hiring baristas — expanding. | T34: Walk-in / Google Maps listing | AB34: Usman & Farhaz Bhadelia (founders) | AC34: https://www.restaurantindia.in/news/restaurant-india-news-brev-opens-new-flagship-caf-in-bandra-expands-community-focused-coffee-concept.n16397 | AE34: Brew: Cold brew; ₹1000 for two | AG34: 3 of 3 read: https://www.restaurantindia.in/news/restaurant-india-news-brev-opens-new-flagship-caf-in-bandra-expands-community-focused-coffee-concept.n16397 https://www.freepressjournal.in/lifestyle/build-your-own-breakfast-board-at-mumbais-newest-caf-run-club-brev-20-that-doesnt-compromise-on-protein-calories https://curlytales.com/bandras-cafe-breve-is-where-your-gym-goals-and-cake-cravings-finally-shake-hands/
A35: C008 | B35: A | C35: New (opened 2026) | D35: Normal | E35: Cocoa & Katli | F35: Bakery / patisserie cafe | G35: West | H35: Maharashtra | I35: Mumbai | J35: Malad (1,050 sq ft) | K35: Unknown | L35: Specialty coffee paired with 'mindful' low-sugar desserts; coffee details not published. | M35: Not published — ask on first contact (look at the retail shelf / bag on the bar) | P35: Premium house espresso blend of Indian estates + one rotating single estate + cold-brew lot. | Q35: Just opened: offer a guest-lot month + free barista calibration; side-by-side cupping against their current beans; ask which roaster/estates they use and what they'd change. | R35: Launched 21 Oct 2026 by Harsh Kedia & Arihant Jain; specialty coffee programme alongside desserts and all-day menu. | S35: Brand-new — still fixing suppliers; pitch a house espresso blend of Indian estates. | T35: Instagram DM | U35: @cocoaandkatli | V35: https://www.instagram.com/cocoaandkatli/ | AB35: Harsh Kedia (chef) & Arihant Jain | AC35: https://aninews.in/news/business/harsh-kedia-and-arihant-jain-launch-cocoa-amp-katli-a-caf233-that-redefines-mindful-indulgence-for-the-conscious-mumbaikar20261021121947/ | AD35: Instagram not indexed by search yet — look up by name on Instagram | AE35: Imported origins: Vietnam | AG35: 2 of 3 read: https://theprint.in/ani-press-releases/harsh-kedia-and-arihant-jain-launch-cocoa-katli-a-cafe-that-redefines-mindful-indulgence-for-the-conscious-mumbaikar/3077520/ https://curlytales.com/india/food/coffee-desserts-mindful-indulgence-harsh-kedia-aka-a-diabetic-chef-opens-new-cafe-in-malad/
A36: C009 | B36: A | C36: New (opened 2026) | D36: Normal | E36: Javaphile | F36: Cafe chain / multi-outlet | G36: West | H36: Maharashtra | I36: Mumbai | J36: Worli flagship (Jan 2026) + Pali Hill, Bandra; sister venue Shelter (Versova) | K36: Unknown | L36: Espresso drinks + flavoured cold brews (citrus, elderflower, sweet lime, cucumber-cream) + manual brews (Chemex, AeroPress, pour-over). | M36: Not published — ask on first contact (look at the retail shelf / bag on the bar) | O36: Roaster not named; flavoured cold brews suit a dedicated cold-brew lot. | P36: Premium house espresso blend of Indian estates + one rotating single estate + cold-brew lot. | Q36: Group pitch across Javaphile Worli, Pali Hill and Shelter: one cold-brew lot + one manual-brew single estate. | R36: Comfort-first cafe focused on great coffee (Foodies of India, Jan 2026). | T36: Walk-in / Google Maps listing | AC36: https://www.restaurantindia.in/news/restaurant-india-news-javaphile-caf-opens-in-worli-mumbai.n14931 | AG36: 3 of 4 read: https://www.restaurantindia.in/news/restaurant-india-news-javaphile-caf-opens-in-worli-mumbai.n14931 https://www.cosmopolitan.in/life/features/story/this-worli-cafe-is-all-about-comfort-caffeine-and-slow-sips-1338113-2026-01-29 https://www.indianretailer.com/news/javaphile-cafe-arrives-worli-deepens-footprint-mumbai
A37: C010 | B37: A | C37: New (opened 2026) | D37: Normal | E37: Pouring Veranda | F37: Independent specialty cafe | G37: West | H37: Maharashtra | I37: Mumbai | J37: Andheri | K37: Unknown | L37: Not published | M37: Not published — ask on first contact (look at the retail shelf / bag on the bar) | P37: Premium house espresso blend of Indian estates + one rotating single estate + cold-brew lot. | Q37: Just opened: offer a guest-lot month + free barista calibration; side-by-side cupping against their current beans; ask which roaster/estates they use and what they'd change. | R37: Listed under 'New Cafes in Andheri' (Foodies of India, Apr 2026). | T37: Walk-in / Google Maps listing | AC37: https://foodiesofindia.wordpress.com/2026/04/02/20-new-restaurants-in-mumbai-to-check-out-april-2026/ | AD37: Wave 4: not found in a web search beyond its source roundup — confirm it is open (Instagram / Google Maps) before outreach. | AG37: 1 of 2 read: https://foodiesofindia.wordpress.com/2026/04/02/20-new-restaurants-in-mumbai-to-check-out-april-2026/
A38: C011 | B38: A | C38: New (opened 2026) | D38: Normal | E38: Rola | F38: All-day / food-led cafe | G38: West | H38: Maharashtra | I38: Mumbai | J38: Pali Hill, Bandra (opened 17 Aug 2026; 70 seats) | K38: Unknown | L38: Flat white, Spanish latte, coffee tonic, mochas; outdoor coffee cart at the entrance. | M38: Not published — ask on first contact (look at the retail shelf / bag on the bar) | N38: ~₹2,000 for two | O38: No filter or single-origin line. | P38: Single-estate tonic / filter line + espresso blend for the cart. | Q38: Offer a cart-friendly espresso blend + one single estate for tonic drinks; propose a cart 'estate of the month'. | R38: All-day diner opened 17 Aug 2026; 70 covers; specialty coffee programme + outdoor coffee cart. | T38: Walk-in / Google Maps listing | AB38: Puneet Anand (Anandvan Resort) | AC38: https://indianretailer.com/news/rola-opens-new-all-day-diner-bandra | AE38: Brew: Flat white, Affogato | AG38: 2 of 2 read: https://indianretailer.com/news/rola-opens-new-all-day-diner-bandra https://www.esquireindia.co.in/food-and-drinks/what-to-eat/from-rola-to-the-mahjong-club-9-new-restaurants-and-cafés-in-mumbai-to-try-this-september
A39: C157 | B39: A | C39: New (opened 2026) | D39: Normal | E39: The Usual | F39: Independent specialty cafe | G39: North | H39: Rajasthan | I39: Jaipur | K39: Unknown | L39: Craft coffee + fruit matchas; sea-salt caramel and burnt-butter lattes; cranberry espresso tonic. | M39: Not published — ask on first contact (look at the retail shelf / bag on the bar) | P39: Premium house espresso blend of Indian estates + one rotating single estate + cold-brew lot. | Q39: Just opened: offer a guest-lot month + free barista calibration; side-by-side cupping against their current beans; ask which roaster/estates they use and what they'd change. | R39: Featured in Outlook Traveller's 'Jaipur is entering its coffee smart era' (Aug 2026). | T39: Walk-in / Google Maps listing | AB39: Dhyaan Kaur (founder) | AC39: https://oteats.outlooktraveller.com/features/guides/jaipur-is-entering-its-coffee-smart-era-and-these-spots-prove-it | AD39: Details thin | AE39: Brew: Espresso tonic | AG39: 1 of 1 read: https://oteats.outlooktraveller.com/features/guides/jaipur-is-entering-its-coffee-smart-era-and-these-spots-prove-it
A40: C173 | B40: A | C40: New (opened 2026) | D40: Normal | E40: CUP | F40: Independent specialty cafe | G40: North | H40: Delhi | I40: New Delhi | J40: Coffee Under Palms — Oasis Bhawan LSC, Vasant Kunj | K40: Unknown | L40: Speciality Arabica; citrusy coffee-and-soda signature; menu still rolling out. | M40: Not published — ask on first contact (look at the retail shelf / bag on the bar) | N40: ~₹1,000 for two | P40: Premium house espresso blend of Indian estates + one rotating single estate + cold-brew lot. | Q40: Just opened: offer a guest-lot month + free barista calibration; side-by-side cupping against their current beans; ask which roaster/estates they use and what they'd change. | R40: New slow-paced cafe (Outlook Traveller Feb 2026 openings). | S40: New — blend + filter. | T40: Walk-in / Google Maps listing | AC40: https://www.oteats.outlooktraveller.com/features/guides/delhis-newest-openings-that-you-must-look-out-for-this-february | AD40: Instagram not indexed by search yet — look up by name on Instagram | AG40: 0 of 1 read:
...

Sheet All Cafes (Premium+Normal)
A1: ID | B1: Priority | C1: Status | D1: Tier | E1: Name | F1: Type | G1: Region | H1: State | I1: City | J1: Area / address | K1: Roasts in-house? | L1: Current coffee roster | M1: Supplier / roaster | N1: Price signals | O1: Gap in their roster | P1: What we can offer | Q1: Approach strategy | R1: Evidence (why this tier) | S1: Pitch angle | T1: Best first contact | U1: Instagram | V1: Instagram URL | W1: Website | X1: Email | Y1: Phone | Z1: LinkedIn | AA1: Listing (Zomato / EazyDiner / Reddit) | AB1: Key people (public) | AC1: Source | AD1: Verify / notes | AE1: Web check: roster evidence (auto — verify) | AF1: Contacts on its own pages | AG1: Pages read (web check)
A2: C001 | B2: B | C2: Established | D2: Normal | E2: Linzz Cafe | F2: Independent specialty cafe | G2: West | H2: Maharashtra | I2: Chhatrapati Sambhajinagar (Aurangabad) | K2: Unknown | L2: Not published | M2: Not published — ask on first contact (look at the retail shelf / bag on the bar) | P2: Premium house espresso blend of Indian estates + one rotating single estate + cold-brew lot. | Q2: Established: position as a second roaster / rotating single estate; walk-in cupping with the head barista. | R2: Instagram bio: 'Artisanal coffee | Authentic global bites'. | S2: Only artisanal-coffee cafe found in city. | T2: Instagram DM | U2: @linzz.csn | V2: https://www.instagram.com/linzz.csn/ | AC2: https://www.instagram.com/linzz.csn/
A3: C002 | B3: C | C3: Established | D3: Normal | E3: EssPressOh Cafe | F3: Independent specialty cafe | G3: West | H3: Maharashtra | I3: Chhatrapati Sambhajinagar (Aurangabad) | J3: API Rd, MIDC Chilkalthana (listed as 'Ess Press Oh') | K3: Unknown | L3: Not published | M3: Not published — ask on first contact (look at the retail shelf / bag on the bar) | N3: 4.1 (148) | P3: Premium house espresso blend of Indian estates + one rotating single estate + cold-brew lot. | Q3: Established: position as a second roaster / rotating single estate; walk-in cupping with the head barista. | R3: Espresso + waffles cafe. | S3: Blend. | T3: Website contact form | W3: http://www.esspressoh.com/ | AC3: http://esspressoh.com/about-us/ | AF3: Esspressohindia@gmail.com · +91 80553 33333 | AG3: 3 of 4 read: http://www.esspressoh.com/ https://esspressoh.com/about-us/ https://esspressoh.com/menu/
A4: C003 | B4: C | C4: Established | D4: Normal | E4: NoMeatNaan | F4: Bakery / patisserie cafe | G4: West | H4: Maharashtra | I4: Chhatrapati Sambhajinagar (Aurangabad) | J4: CIDCO + Connaught | K4: Unknown | L4: Not published | M4: Not published — ask on first contact (look at the retail shelf / bag on the bar) | P4: Premium house espresso blend of Indian estates + one rotating single estate + cold-brew lot. | Q4: Established: position as a second roaster / rotating single estate; walk-in cupping with the head barista. | R4: Bakery and coffee shop (Instagram). | T4: Instagram DM | U4: @nomeatnaan_bakery | V4: https://www.instagram.com/nomeatnaan_bakery/ | AC4: https://www.instagram.com/nomeatnaan_bakery/ | AD4: Wave 4: not found in a web search beyond its source roundup — confirm it is open (Instagram / Google Maps) before outreach.
A5: C004 | B5: C | C5: Established | D5: Normal | E5: Coffee Sanskruti | F5: Independent specialty cafe | G5: West | H5: Maharashtra | I5: Kolhapur | J5: S2 Royal Classic, Rajarampuri 3rd Lane, near Jain Temple | K5: Unknown | L5: Small coffee bar: hot and cold coffees; 4.4 (97); closed Mondays. | M5: Not published — ask on first contact (look at the retail shelf / bag on the bar) | P5: Premium house espresso blend of Indian estates + one rotating single estate + cold-brew lot. | Q5: Established: position as a second roaster / rotating single estate; walk-in cupping with the head barista. | R5: Self-described premium coffee cafe. | S5: Blend. | T5: Call / WhatsApp | W5: https://www.coffeesanskruti.com/ | Y5: +91 96737 35453 (Yappe) | AC5: https://www.coffeesanskruti.com/ | AE5: Brew: Cold brew; Commodity brands: Starbucks | AF5: coffeesanskruti@gmail.com · +91 96737 35453 | AG5: 2 of 2 read: https://www.coffeesanskruti.com/ https://yappe.in/maharashtra/kolhapur/coffee-sanskruti/225223
